<?xml version="1.0"?>

<robot name="visionnav_robot">

  <!-- ================= BASE ================= -->
  <link name="base_link">

    <visual>
      <geometry>
        <box size="0.6 0.4 0.2"/>
      </geometry>
      <material name="blue">
        <color rgba="0 0 1 1"/>
      </material>
    </visual>

    <collision>
      <geometry>
        <box size="0.6 0.4 0.2"/>
      </geometry>
    </collision>

    <inertial>
      <mass value="2.0"/>
      <inertia ixx="0.01" ixy="0.0" ixz="0.0"
               iyy="0.02" iyz="0.0"
               izz="0.03"/>
    </inertial>

  </link>

  <!-- ================= LEFT WHEEL ================= -->
  <link name="left_wheel_link">

    <visual>
      <origin xyz="0 0 0" rpy="1.5708 0 0"/>
      <geometry>
        <cylinder radius="0.07" length="0.04"/>
      </geometry>
      <material name="black">
        <color rgba="0.1 0.1 0.1 1"/>
      </material>
    </visual>

    <collision>
      <origin xyz="0 0 0" rpy="1.5708 0 0"/>
      <geometry>
        <cylinder radius="0.07" length="0.04"/>
      </geometry>
    </collision>

    <inertial>
      <mass value="0.2"/>
      <inertia ixx="0.00058" ixy="0" ixz="0"
               iyy="0.00049" iyz="0"
               izz="0.00058"/>
    </inertial>

  </link>

  <joint name="left_wheel_joint" type="continuous">
    <parent link="base_link"/>
    <child link="left_wheel_link"/>
    <origin xyz="0 0.22 -0.1" rpy="0 0 0"/>
    <axis xyz="0 1 0"/>
  </joint>

  <!-- ================= RIGHT WHEEL ================= -->
  <link name="right_wheel_link">

    <visual>
      <origin xyz="0 0 0" rpy="1.5708 0 0"/>
      <geometry>
        <cylinder radius="0.07" length="0.04"/>
      </geometry>
      <material name="black">
        <color rgba="0.1 0.1 0.1 1"/>
      </material>
    </visual>

    <collision>
      <origin xyz="0 0 0" rpy="1.5708 0 0"/>
      <geometry>
        <cylinder radius="0.07" length="0.04"/>
      </geometry>
    </collision>

    <inertial>
      <mass value="0.2"/>
      <inertia ixx="0.00058" ixy="0" ixz="0"
               iyy="0.00049" iyz="0"
               izz="0.00058"/>
    </inertial>

  </link>

  <joint name="right_wheel_joint" type="continuous">
    <parent link="base_link"/>
    <child link="right_wheel_link"/>
    <origin xyz="0 -0.22 -0.1" rpy="0 0 0"/>
    <axis xyz="0 1 0"/>
  </joint>

  <!-- ================= CASTER (REAR) ================= -->
  <link name="caster_rear_link">

    <visual>
      <geometry>
        <sphere radius="0.05"/>
      </geometry>
      <material name="gray">
        <color rgba="0.5 0.5 0.5 1"/>
      </material>
    </visual>

    <collision>
      <geometry>
        <sphere radius="0.05"/>
      </geometry>
    </collision>

    <inertial>
      <mass value="0.1"/>
      <inertia ixx="0.0001" ixy="0" ixz="0"
               iyy="0.0001" iyz="0"
               izz="0.0001"/>
    </inertial>

  </link>

  <joint name="caster_rear_joint" type="fixed">
    <parent link="base_link"/>
    <child link="caster_rear_link"/>
    <origin xyz="-0.25 0 -0.12"/>
  </joint>

  <!-- ================= CASTER (FRONT) ================= -->
  <link name="caster_front_link">

    <visual>
      <geometry>
        <sphere radius="0.05"/>
      </geometry>
      <material name="gray">
        <color rgba="0.5 0.5 0.5 1"/>
      </material>
    </visual>

    <collision>
      <geometry>
        <sphere radius="0.05"/>
      </geometry>
    </collision>

    <inertial>
      <mass value="0.1"/>
      <inertia ixx="0.0001" ixy="0" ixz="0"
               iyy="0.0001" iyz="0"
               izz="0.0001"/>
    </inertial>

  </link>

  <joint name="caster_front_joint" type="fixed">
    <parent link="base_link"/>
    <child link="caster_front_link"/>
    <origin xyz="0.25 0 -0.12"/>
  </joint>

  <!-- ================= LIDAR ================= -->
  <link name="lidar_link"/>

  <joint name="lidar_joint" type="fixed">
    <parent link="base_link"/>
    <child link="lidar_link"/>
    <origin xyz="0 0 0.15"/>
  </joint>

  <gazebo reference="lidar_link">
    <sensor name="lidar_sensor" type="ray">
      <always_on>true</always_on>
      <update_rate>10</update_rate>
      <visualize>true</visualize>

      <ray>
        <scan>
          <horizontal>
            <samples>360</samples>
            <min_angle>-3.14159</min_angle>
            <max_angle>3.14159</max_angle>
          </horizontal>
        </scan>

        <range>
          <min>0.12</min>
          <max>10.0</max>
        </range>
      </ray>

      <plugin name="gazebo_ros_laser" filename="libgazebo_ros_ray_sensor.so">
        <ros>
          <remapping>~/out:=scan</remapping>
        </ros>
        <output_type>sensor_msgs/LaserScan</output_type>
        <frame_name>lidar_link</frame_name>
      </plugin>
    </sensor>
  </gazebo>

  <!-- ================= IMU ================= -->
  <gazebo reference="base_link">
    <sensor name="imu_sensor" type="imu">
      <always_on>true</always_on>
      <update_rate>50</update_rate>

      <plugin name="imu_plugin" filename="libgazebo_ros_imu_sensor.so">
        <ros>
          <namespace>/imu</namespace>
          <remapping>~/out:=data</remapping>
        </ros>
        <initial_orientation_as_reference>false</initial_orientation_as_reference>
      </plugin>
    </sensor>
  </gazebo>

  <!-- ================= RGB CAMERA ================= -->
  <link name="rgb_camera_link"/>

  <joint name="rgb_camera_joint" type="fixed">
    <parent link="base_link"/>
    <child link="rgb_camera_link"/>
    <origin xyz="0.3 0 0.05"/>
  </joint>

  <gazebo reference="rgb_camera_link">
    <sensor name="rgb_camera" type="camera">
      <always_on>true</always_on>
      <update_rate>30</update_rate>

      <camera>
        <horizontal_fov>1.5</horizontal_fov>
        <image>
          <width>640</width>
          <height>480</height>
          <format>R8G8B8</format>
        </image>
        <clip>
          <near>0.05</near>
          <far>50</far>
        </clip>
      </camera>

      <plugin name="camera_plugin" filename="libgazebo_ros_camera.so">
        <ros>
          <namespace></namespace>
        </ros>
        <camera_name>camera</camera_name>
        <frame_name>rgb_camera_link</frame_name>
      </plugin>
    </sensor>
  </gazebo>

  <!-- ================= DEPTH CAMERA ================= -->
  <link name="depth_camera_link"/>

  <joint name="depth_camera_joint" type="fixed">
    <parent link="base_link"/>
    <child link="depth_camera_link"/>
    <origin xyz="0.3 0 -0.05"/>
  </joint>

  <gazebo reference="depth_camera_link">
    <sensor name="depth_camera" type="depth">
      <always_on>true</always_on>
      <update_rate>30</update_rate>

      <camera>
        <horizontal_fov>1.5</horizontal_fov>
        <image>
          <width>640</width>
          <height>480</height>
        </image>
        <clip>
          <near>0.1</near>
          <far>10.0</far>
        </clip>
      </camera>

      <plugin name="depth_plugin" filename="libgazebo_ros_camera.so">
        <ros>
          <namespace></namespace>
        </ros>
        <camera_name>depth</camera_name>
        <frame_name>depth_camera_link</frame_name>
      </plugin>
    </sensor>
  </gazebo>


  <!-- ================= FRICTION ================= -->
  <gazebo reference="left_wheel_link">
    <mu1>2.0</mu1>
    <mu2>2.0</mu2>
    <kp>100000</kp>
    <kd>1</kd>
  </gazebo>

  <gazebo reference="right_wheel_link">
    <mu1>2.0</mu1>
    <mu2>2.0</mu2>
    <kp>100000</kp>
    <kd>1</kd>
  </gazebo>

  <gazebo reference="caster_rear_link">
    <mu1>0.0</mu1>
    <mu2>0.0</mu2>
  </gazebo>

  <gazebo reference="caster_front_link">
    <mu1>0.0</mu1>
    <mu2>0.0</mu2>
  </gazebo>

  <!-- ================= ROS2 CONTROL ================= -->
  <ros2_control name="GazeboSystem" type="system">

    <hardware>
      <plugin>gazebo_ros2_control/GazeboSystem</plugin>
    </hardware>

    <joint name="left_wheel_joint">
      <command_interface name="velocity"/>
      <state_interface name="position"/>
      <state_interface name="velocity"/>
    </joint>

    <joint name="right_wheel_joint">
      <command_interface name="velocity"/>
      <state_interface name="position"/>
      <state_interface name="velocity"/>
    </joint>

  </ros2_control>

  <gazebo>
    <plugin name="gazebo_ros2_control" filename="libgazebo_ros2_control.so">
      <parameters>ROBOT_SIMULATION_DIFF_DRIVE_CONFIG_PATH</parameters>
    </plugin>
  </gazebo>

</robot>